Workbook
Name SegmentaciónDeDatos_MEDIDAS: #N/A
Name SegmentaciónDeDatos_SUB_MEDIDAS: #N/A

Sheet Análisis NSI
A4: MEDIDAS | B4: ETT | G4: MEDIDAS | H4: =A5 -> ORGANIZATIVAS ETT 2025 | I4: =A6 -> ADMINISTRATIVAS ETT 2025 | J4: =A7 -> JURIDICAS ETT 2025 | K4: =A8 -> FISICAS - OPERATIVAS ETT 2025 | L4: =A9 -> FISICAS - INFRAESTRUCTURA ETT 2025 | M4: =A10 -> TÉCNICAS - COMPETENCIAS ETT 2025 | N4: =A11 -> TÉCNICAS - INFRAESTRUCTURA ETT 2025 | P4: =+A17 -> PROMEDIO EET 2025 | R4: =$A$42 -> PROMEDIO EET PROYECTADO (2026)
A5: ORGANIZATIVAS ETT 2025 | B5: =AVERAGEIF('Resumen NSI'!$C$3:$C$16,"<>0") -> 2.3571429 | G5: PROMEDIO | H5: =B5 -> 2.3571429 | I5: =B6 -> 2.5833333 | J5: =B7 -> 1.1111111 | K5: =B8 -> 1.25 | L5: =B9 -> 2.75 | M5: =B10 -> 1.25 | N5: =B11 -> 3.2 | P5: =+B17 -> 2.0797817 | R5: =$B$42 -> 3.0907937
A6: ADMINISTRATIVAS ETT 2025 | B6: =AVERAGEIF('Resumen NSI'!C17:C29,"<>0") -> 2.5833333
A7: JURIDICAS ETT 2025 | B7: =AVERAGEIF('Resumen NSI'!C30:C40,"<>0") -> 1.1111111
A8: FISICAS - OPERATIVAS ETT 2025 | B8: =AVERAGEIF('Resumen NSI'!C41:C48,"<>0") -> 1.25
A9: FISICAS - INFRAESTRUCTURA ETT 2025 | B9: =AVERAGEIF('Resumen NSI'!C49:C56,"<>0") -> 2.75 | G9: =H4 -> ORGANIZATIVAS ETT 2025 | J9: =I4 -> ADMINISTRATIVAS ETT 2025 | M9: =J4 -> JURIDICAS ETT 2025 | P9: =K4 -> FISICAS - OPERATIVAS ETT 2025 | S9: =L4 -> FISICAS - INFRAESTRUCTURA ETT 2025 | V9: =M4 -> TÉCNICAS - COMPETENCIAS ETT 2025 | Y9: =N4 -> TÉCNICAS - INFRAESTRUCTURA ETT 2025 | AB9: =+P4 -> PROMEDIO EET 2025
A10: TÉCNICAS - COMPETENCIAS ETT 2025 | B10: =AVERAGEIF('Resumen NSI'!C57:C64,"<>0") -> 1.25 | G10: INDICADOR | H10: =H5-0.05 -> 2.3071429 | J10: INDICADOR | K10: =I5-0.5 -> 2.0833333 | M10: INDICADOR | N10: =J5-0.05 -> 1.0611111 | P10: INDICADOR | Q10: =K5-0.05 -> 1.2 | S10: INDICADOR | T10: =L5-0.05 -> 2.7 | V10: INDICADOR | W10: =M5-0.05 -> 1.2 | Y10: INDICADOR | Z10: =N5-0.05 -> 3.15 | AB10: INDICADOR | AC10: =$P$5 -> 2.0797817
A11: TÉCNICAS - INFRAESTRUCTURA ETT 2025 | B11: =AVERAGEIF('Resumen NSI'!C65:C74,"<>0") -> 3.2 | G11: AGUJA | H11: 0.1 | J11: AGUJA | K11: 0.1 | M11: AGUJA | N11: 0.1 | P11: AGUJA | Q11: 0.1 | S11: AGUJA | T11: 0.1 | V11: AGUJA | W11: =0.1 -> 0.1 | Y11: AGUJA | Z11: 0.1 | AB11: AGUJA | AC11: 0.1
G12: RESTO | H12: =8-H10-H11 -> 5.5928571 | J12: RESTO | K12: =8-K10-K11 -> 5.8166667 | M12: RESTO | N12: =8-N10-N11 -> 6.8388889 | P12: RESTO | Q12: =8-Q10-Q11 -> 6.7 | S12: RESTO | T12: =8-T10-T11 -> 5.2 | V12: RESTO | W12: =8-W10-W11 -> 6.7 | Y12: RESTO | Z12: =8-Z10-Z11 -> 4.75 | AB12: RESTO | AC12: =8-AC10-AC11 -> 5.8202183
A15: NIVEL DE SEGURIDAD INICIAL | B15: ='NIVEL DE SEGURIDAD'!$I$15 -> 2.0199454
A17: PROMEDIO EET 2025 | B17: =+(B5*0.3)+(B6*0.2)+(B7*0.2)+(B8+B9+B10+B11)/4*0.3 -> 2.0797817
F27: 4 | G27: 5 | H27: 6 | I27: 7 | J27: 8 | K27: 9 | L27: 10 | M27: 11 | N27: 12 | O27: 13 | P27: 14 | Q27: 15 | R27: 16
F28: POBRE | I28: MEDIO BAJO | M28: MEDIO ALTO | Q28: PROFESIONAL
A32: PROYECTADO
A33: MEDIDAS | B33: PANSI | G33: MEDIDAS | H33: =A34 -> ORGANIZATIVAS PROYECTADA | I33: =A35 -> ADMINISTRATIVAS PROYECTADA | J33: =A36 -> JURIDICAS PROYECTADA | K33: =A37 -> FISICAS - OPERATIVAS PROYECTADA | L33: =A38 -> FISICAS - INFRAESTRUCTURA PROYECTADA | M33: =A39 -> TÉCNICAS - COMPETENCIAS PROYECTADA | N33: =A40 -> TÉCNICAS - INFRAESTRUCTURA PROYECTADA
A34: ORGANIZATIVAS PROYECTADA | B34: ='ORGANIZATIVAS EET + PANSI 2026'!$K$25 -> 3 | G34: PROMEDIO | H34: =B34 -> 3 | I34: =B35 -> 3 | J34: =B36 -> 3.1111111 | K34: =B37 -> 3.2 | L34: =B38 -> 3 | M34: =B39 -> 3 | N34: =B40 -> 3.7142857
A35: ADMINISTRATIVAS PROYECTADA | B35: ='ADMINISTRATI EET + PANSI 2026'!$K$25 -> 3
A36: JURIDICAS PROYECTADA | B36: ='JURÍDICAS EET + PANSI 2026'!$K$23 -> 3.1111111
A37: FISICAS - OPERATIVAS PROYECTADA | B37: =AVERAGEIF('Resumen NSI'!C70:C77,"<>0") -> 3.2
A38: FISICAS - INFRAESTRUCTURA PROYECTADA | B38: ='FÍSICAS - INFRSTRA EET + PANSI'!$K$20 -> 3 | G38: =H33 -> ORGANIZATIVAS PROYECTADA | J38: =I33 -> ADMINISTRATIVAS PROYECTADA | M38: =J33 -> JURIDICAS PROYECTADA | P38: =K33 -> FISICAS - OPERATIVAS PROYECTADA | S38: =L33 -> FISICAS - INFRAESTRUCTURA PROYECTADA | V38: =M33 -> TÉCNICAS - COMPETENCIAS PROYECTADA | Y38: =N33 -> TÉCNICAS - INFRAESTRUCTURA PROYECTADA
A39: TÉCNICAS - COMPETENCIAS PROYECTADA | B39: ='TÉCNICAS COMPET EET + PANSI'!$K$21 -> 3 | G39: INDICADOR | H39: =H34-0.05 -> 2.95 | J39: INDICADOR | K39: =I34-0.5 -> 2.5 | M39: INDICADOR | N39: =J34-0.05 -> 3.0611111 | P39: INDICADOR | Q39: =K34-0.05 -> 3.15 | S39: INDICADOR | T39: =L34-0.05 -> 2.95 | V39: INDICADOR | W39: =M34-0.05 -> 2.95 | Y39: INDICADOR | Z39: =N34-0.05 -> 3.6642857
A40: TÉCNICAS - INFRAESTRUCTURA PROYECTADA | B40: ='TÉCNICAS TECNOL EET + PANSI'!$K$21 -> 3.7142857 | G40: AGUJA | H40: 0.1 | J40: AGUJA | K40: 0.1 | M40: AGUJA | N40: 0.1 | P40: AGUJA | Q40: 0.1 | S40: AGUJA | T40: 0.1 | V40: AGUJA | W40: =0.1 -> 0.1 | Y40: AGUJA | Z40: 0.1
G41: RESTO | H41: =8-H39-H40 -> 4.95 | J41: RESTO | K41: =8-K39-K40 -> 5.4 | M41: RESTO | N41: =8-N39-N40 -> 4.8388889 | P41: RESTO | Q41: =8-Q39-Q40 -> 4.75 | S41: RESTO | T41: =8-T39-T40 -> 4.95 | V41: RESTO | W41: =8-W39-W40 -> 4.95 | Y41: RESTO | Z41: =8-Z39-Z40 -> 4.2357143
A42: PROMEDIO EET PROYECTADO (2026) | B42: =+(B34*0.3)+(B35*0.2)+(B36*0.2)+(B37+B38+B39+B40)/4*0.3 -> 3.0907937
A44: NIVEL DE SEGURIDAD PROYECTADO
K60: =R4 -> PROMEDIO EET PROYECTADO (2026)
K61: INDICADOR | L61: =R5-0.5 -> 2.5907937
K62: AGUJA | L62: 0.1
K63: RESTO | L63: =8-L61-L62 -> 5.3092063

Sheet Resumen NSI
A2: MEDIDAS | B2: SUB MEDIDAS | C2: NSI | D2: WEB | E2: DIGITAL | F2: PATD | G2: REMOTO | H2: CALIFICACIÓN | L2: 1
A3: ORGANIZATIVAS | B3: JERARQUIAS | C3: ='EET DIC 2025'!I15 -> 3 | L3: 2
A4: ORGANIZATIVAS | B4: ROLES | C4: ='EET DIC 2025'!I16 -> 3 | L4: 3
A5: ORGANIZATIVAS | B5: DEFINICIÓN CONTEXTOS | C5: ='EET DIC 2025'!I17 -> 1 | L5: 4
A6: ORGANIZATIVAS | B6: IDENTIFICACIÓN 3ras PARTES | C6: ='EET DIC 2025'!I18 -> 3
A7: ORGANIZATIVAS | B7: IDENTIFICACIÓN ÁMBITOS | C7: ='EET DIC 2025'!I19 -> 2
A8: ORGANIZATIVAS | B8: GESTIÓN POR ÁMBITOS | C8: ='EET DIC 2025'!I20 -> 3
A9: ORGANIZATIVAS | B9: ESTRATEGIA | C9: ='EET DIC 2025'!I21 -> 3
A10: ORGANIZATIVAS | B10: PLAN ESTRATÉGICO | C10: ='EET DIC 2025'!I22 -> 1
A11: ORGANIZATIVAS | B11: PLAN CONTINUIDAD | C11: ='EET DIC 2025'!I23 -> 3
A12: ORGANIZATIVAS | B12: DOCUMENTACIÓN GRC | C12: ='EET DIC 2025'!I24 -> 3
A13: ORGANIZATIVAS | B13: GESTIÓN TALENTO | C13: ='EET DIC 2025'!I25 -> 1
A14: ORGANIZATIVAS | B14: GESTIÓN DEL CAMBIO | C14: ='EET DIC 2025'!I26 -> 3
A15: ORGANIZATIVAS | B15: TOMA DE DECISIONES | C15: ='EET DIC 2025'!I27 -> 2
A16: ORGANIZATIVAS | B16: SANCIONES Y RECOMPENSAS | C16: ='EET DIC 2025'!I28 -> 2
A17: ADMINISTRATIVAS | B17: SANCIONES Y RECOMPENSAS | C17: ='EET DIC 2025'!Q15 -> 3
A18: ADMINISTRATIVAS | B18: EVALUACIONES INTERNAS | C18: ='EET DIC 2025'!Q16 -> 4
A19: ADMINISTRATIVAS | B19: EVALUACIÓN 3ras PARTES | C19: ='EET DIC 2025'!Q17 -> 3
A20: ADMINISTRATIVAS | B20: INGRESOS Y DESVINCULACIÓN | C20: ='EET DIC 2025'!Q18 -> 2
A21: ADMINISTRATIVAS | B21: MEJORA CONTINUA Y RESILIENCIA | C21: ='EET DIC 2025'!Q19 -> 2
A22: ADMINISTRATIVAS | B22: GESTIÓN DE INDICADORES | C22: ='EET DIC 2025'!Q20 -> 3
A23: ADMINISTRATIVAS | B23: PLAN AUDITORÍAS INTERNAS | C23: ='EET DIC 2025'!Q21 -> 4
A24: ADMINISTRATIVAS | B24: PLAN AUDITOÍAS 3ras PARTES | C24: ='EET DIC 2025'!Q22 -> 1
A25: ADMINISTRATIVAS | B25: PLAN DE SIMULACROS | C25: ='EET DIC 2025'!Q23 -> 0
A26: ADMINISTRATIVAS | B26: SIMULACROS 3ras PARTES | C26: ='EET DIC 2025'!Q24 -> 3
A27: ADMINISTRATIVAS | B27: MODELO DE GESTIÓN | C27: ='EET DIC 2025'!Q25 -> 3
A28: ADMINISTRATIVAS | B28: CUMPLIMIENTO DOCUMENTAL | C28: ='EET DIC 2025'!Q26 -> 2
A29: ADMINISTRATIVAS | B29: ESTACIONES AUTOGESTIONADAS | C29: ='EET DIC 2025'!Q27 -> 1
A30: JURIDICAS | B30: COMUNICADOS | C30: ='EET DIC 2025'!Y15 -> 1
A31: JURIDICAS | B31: CONTRATOS | C31: ='EET DIC 2025'!Y16 -> 2
A32: JURIDICAS | B32: RESPUESTAS | C32: ='EET DIC 2025'!Y17 -> 1
A33: JURIDICAS | B33: REGISTROS ANTE SPDP | C33: ='EET DIC 2025'!Y18 -> 1
A34: JURIDICAS | B34: EVALUACIONES JURÍDICAS | C34: ='EET DIC 2025'!Y19 -> 1
A35: JURIDICAS | B35: GESTIÓN POR ÁMBITOS | C35: ='EET DIC 2025'!Y20 -> 1
A36: JURIDICAS | B36: POLÍTICAS MARCO LEGAL VIGENTE | C36: ='EET DIC 2025'!Y21 -> 1
A37: JURIDICAS | B37: EJERCICIO DE DERECHOS | C37: ='EET DIC 2025'!Y22 -> 1
A38: JURIDICAS | B38: GARANTIAS ADECUADAS | C38: ='EET DIC 2025'!Y23 -> 0
A39: JURIDICAS | B39: DOCUMENTACIÓN GRC | C39: ='EET DIC 2025'!Y24 -> 1
A40: JURIDICAS | B40: NORMAS CORPORATIVAS VINCULANTES | C40: ='EET DIC 2025'!Y25 -> 0
A41: FISICAS - OPERATIVAS | B41: MAPEO PATD | C41: ='EET DIC 2025'!I35 -> 1
...

Sheet EET DIC 2025
H1: https://patrimonial.com.ec/
D2: MATRIZ DE CRITERIOS DE MADUREZ ORGANIZACIONAL
D3: CAÓTICO (1) | E3: MEDIO BAJO (2) | F3: MEDIO ALTO (3) | G3: PROFESIONAL (4)
C4: MADUREZ ORGANIZACIONAL | D4: PROMEDIO Art. 47.2, LOPDP:2021 | E4: PROMEDIO Art. 47.2, LOPDP:2021 | F4: PROMEDIO Art. 47.2, LOPDP:2021 | G4: PROMEDIO Art. 47.2, LOPDP:2021
C5: SISTEMA DE GESTIÓN | D5: INEXISTENTE | E5: NO VALIDADO | F5: VALIDADO Y POCO MANTENIDO, NO MEJORA NI RESILIENTE | G5: VALIDADO, ANTENIDO, MEJORADO Y RESILIENTE
C6: TOMA DE DECISIONES | D6: INEXISTENTE | E6: POR JERARQUIAS | F6: COMBINA INDICADORES Y PREVALECE JERARQUIAS | G6: INDICADORES
C7: ENFOQUE DE RESULTADOS | D7: INEXISTENTE | E7: REACTIVO POR ATENCIÓN DE EMERGENCIAS | F7: COMBINADO Y PREVALECE LO REACTIVO | G7: RIESGOS Y CONTINUIDAD DEL NEGOCIO
D11: ORGANIZATIVAS | L11: ADMINISTRATIVAS | T11: JURÍDICAS
E12: PSEUDO - PROFESIONAL | M12: PSEUDO - PROFESIONAL | U12: PSEUDO - PROFESIONAL
D13: CAÓTICO (1) | E13: MEDIO BAJO (2) | F13: MEDIO ALTO (3) | G13: PROFESIONAL (4) | H13: COMENTARIO | L13: CAÓTICO (1) | M13: MEDIO BAJO (2) | N13: MEDIO ALTO (3) | O13: PROFESIONAL (4) | P13: COMENTARIO | T13: CAÓTICO (1) | U13: MEDIO BAJO (2) | V13: MEDIO ALTO (3) | W13: PROFESIONAL (4) | X13: COMENTARIO
C14: MODELO DE GESTIÓN - WORKING SYSTEM | D14: INEXISTENTE | E14: EMPÍRICO, POCA DOCUMENTACIÓN, TODO ES INFORMAL | F14: TAREAS DOCUMENTADAS, TÉCNICAS, MÉTODO SIN RIGUROSIDAD | G14: MODELO RIGUROSO y TÉCNICO | K14: MODELO DE GESTIÓN - WORKING SYSTEM | L14: INEXISTENTE | M14: EMPÍRICO, POCA DOCUMENTACIÓN, TODO ES INFORMAL | N14: TAREAS DOCUMENTADAS, TÉCNICAS, MÉTODO SIN RIGUROSIDAD | O14: MODELO RIGUROSO y TÉCNICO | S14: MODELO DE GESTIÓN - WORKING SYSTEM | T14: INEXISTENTE | U14: EMPÍRICO, POCA DOCUMENTACIÓN, TODO ES INFORMAL | V14: TAREAS DOCUMENTADAS, TÉCNICAS, MÉTODO SIN RIGUROSIDAD | W14: MODELO RIGUROSO y TÉCNICO
C15: JERARQUIAS | F15: X | H15: EXISTE UN ORGANIGRAMA , EXISTEN INCOMPATIBILIDADES ENTRE CARGOS, NO EST[AN IDENTIFICADAS LAS OFICINAS TOPOLOGICAMENTE, LO BUENO ES QUE TODO ESTA ORGANIZADITO. | I15: {=IFERROR(_xlfn.IFS(D15="X",1,E15="X",2,F15="X",3,G15="X",4),0)} -> 3 | K15: SANCIONES Y RECOMPENSAS | N15: X | P15: SE DEBE ACTUALIZAR, NO STA NORMADO LA PARTE DE RECOMPENSAS PERO SI HAY ALGUNOS INCENTIVOS | Q15: {=IFERROR(_xlfn.IFS(L15="X",1,M15="X",2,N15="X",3,O15="X",4),0)} -> 3 | S15: COMUNICADOS | T15: X | Y15: {=IFERROR(_xlfn.IFS(T15="X",1,U15="X",2,V15="X",3,W15="X",4),0)} -> 1
C16: CARGOS | F16: X | H16: HAY QUE ACTULIZARLOS, HAY QUE REVISAR INCONSISTENCIAS, HAY COMITES CNSTITUIDOS POR RESOLUCI[ON. | I16: {=IFERROR(_xlfn.IFS(D16="X",1,E16="X",2,F16="X",3,G16="X",4),0)} -> 3 | K16: EVALUACIONES INTERNAS | O16: X | P16: EXISTE TODAS LAS RESOLUCIONES QUE IMPONE LA SEPD., EXITE RESOLUCION 360 POR APRBACI[ON | Q16: {=IFERROR(_xlfn.IFS(L16="X",1,M16="X",2,N16="X",3,O16="X",4),0)} -> 4 | S16: CONTRATOS | U16: X | Y16: {=IFERROR(_xlfn.IFS(T16="X",1,U16="X",2,V16="X",3,W16="X",4),0)} -> 2
C17: DEFINICIÓN CONTEXTOS | D17: X | I17: {=IFERROR(_xlfn.IFS(D17="X",1,E17="X",2,F17="X",3,G17="X",4),0)} -> 1 | K17: EVALUACIÓN 3ras PARTES | N17: X | P17: SOLO LOS DE LOS QUE EXIGGE LA UAFE | Q17: {=IFERROR(_xlfn.IFS(L17="X",1,M17="X",2,N17="X",3,O17="X",4),0)} -> 3 | S17: RESPUESTAS | T17: X | Y17: {=IFERROR(_xlfn.IFS(T17="X",1,U17="X",2,V17="X",3,W17="X",4),0)} -> 1
C18: IDENTIFICACIÓN 3ras PARTES | F18: X | H18: SIEXISTE ALGO DE BIA | I18: {=IFERROR(_xlfn.IFS(D18="X",1,E18="X",2,F18="X",3,G18="X",4),0)} -> 3 | K18: INGRESOS Y DESVINCULACIÓN | M18: X | P18: NO SE CUMPLE DE MANERA RIGUROSA. | Q18: {=IFERROR(_xlfn.IFS(L18="X",1,M18="X",2,N18="X",3,O18="X",4),0)} -> 2 | S18: REGISTROS ANTE SPDP | T18: X | Y18: {=IFERROR(_xlfn.IFS(T18="X",1,U18="X",2,V18="X",3,W18="X",4),0)} -> 1
C19: IDENTIFICACIÓN ÁMBITOS | E19: X | H19: EXISTEN EN LOS MANUALES, NO ESTAN LOS DE MARKETING ESTAN LEVANTANDO PROCEDIMEINTOS, LOS VPN ESTAN BIEN PROCEDIMEINTADAS | I19: {=IFERROR(_xlfn.IFS(D19="X",1,E19="X",2,F19="X",3,G19="X",4),0)} -> 2 | K19: MEJORA CONTINUA Y RESILIENCIA | M19: X | Q19: {=IFERROR(_xlfn.IFS(L19="X",1,M19="X",2,N19="X",3,O19="X",4),0)} -> 2 | S19: EVALUACIONES JURÍDICAS | T19: X | Y19: {=IFERROR(_xlfn.IFS(T19="X",1,U19="X",2,V19="X",3,W19="X",4),0)} -> 1
C20: GESTIÓN POR ÁMBITOS | F20: X | H20: ESTAN PROCEDIMENTADOS | I20: {=IFERROR(_xlfn.IFS(D20="X",1,E20="X",2,F20="X",3,G20="X",4),0)} -> 3 | K20: GESTIÓN DE INDICADORES | N20: X | P20: SOLO LOS QUE PIDE LA NORMA | Q20: {=IFERROR(_xlfn.IFS(L20="X",1,M20="X",2,N20="X",3,O20="X",4),0)} -> 3 | S20: GESTIÓN POR ÁMBITOS | T20: X | Y20: {=IFERROR(_xlfn.IFS(T20="X",1,U20="X",2,V20="X",3,W20="X",4),0)} -> 1
C21: ESTRATEGIA | F21: X | H21: EXISTE TODO EL MODELO, FALTAN LOS PRINCIPIOS | I21: {=IFERROR(_xlfn.IFS(D21="X",1,E21="X",2,F21="X",3,G21="X",4),0)} -> 3 | K21: PLAN AUDITORÍAS INTERNAS | O21: X | P21: SOLO LOS QUE DEFINE AREA DE AUDITORIA INTERNA | Q21: {=IFERROR(_xlfn.IFS(L21="X",1,M21="X",2,N21="X",3,O21="X",4),0)} -> 4 | S21: POLÍTICAS MARCO LEGAL VIGENTE | T21: X | Y21: {=IFERROR(_xlfn.IFS(T21="X",1,U21="X",2,V21="X",3,W21="X",4),0)} -> 1
C22: PLAN ESTRATÉGICO | D22: X | H22: ES INEXISTENTE PARA LOS MAS OPERATIVOS, NO ESTA SOCIALIZADO, NO SE SABE SI ESTA ASOCIADA LA NORMATIVA COMO | I22: {=IFERROR(_xlfn.IFS(D22="X",1,E22="X",2,F22="X",3,G22="X",4),0)} -> 1 | K22: PLAN AUDITOÍAS 3ras PARTES | L22: X | Q22: {=IFERROR(_xlfn.IFS(L22="X",1,M22="X",2,N22="X",3,O22="X",4),0)} -> 1 | S22: EJERCICIO DE DERECHOS | T22: X | Y22: {=IFERROR(_xlfn.IFS(T22="X",1,U22="X",2,V22="X",3,W22="X",4),0)} -> 1
C23: PLAN CONTINUIDAD | F23: X | H23: ACTUALIZAR PDP | I23: {=IFERROR(_xlfn.IFS(D23="X",1,E23="X",2,F23="X",3,G23="X",4),0)} -> 3 | K23: PLAN DE SIMULACROS | Q23: {=IFERROR(_xlfn.IFS(L23="X",1,M23="X",2,N23="X",3,O23="X",4),0)} -> 0 | S23: GARANTIAS ADECUADAS | Y23: {=IFERROR(_xlfn.IFS(T23="X",1,U23="X",2,V23="X",3,W23="X",4),0)} -> 0
C24: DOCUMENTACIÓN GRC | F24: X | H24: ACTALIZAR LEY DE PDP | I24: {=IFERROR(_xlfn.IFS(D24="X",1,E24="X",2,F24="X",3,G24="X",4),0)} -> 3 | K24: SIMULACROS 3ras PARTES | N24: X | P24: INCLUYE LOS DE SEGURIDAD DE LA INFORMACI[ON | Q24: {=IFERROR(_xlfn.IFS(L24="X",1,M24="X",2,N24="X",3,O24="X",4),0)} -> 3 | S24: DOCUMENTACIÓN GRC | T24: X | Y24: {=IFERROR(_xlfn.IFS(T24="X",1,U24="X",2,V24="X",3,W24="X",4),0)} -> 1
C25: GESTIÓN TALENTO | D25: X | H25: NO EXISTE FORMALMENTE POR POSICION | I25: {=IFERROR(_xlfn.IFS(D25="X",1,E25="X",2,F25="X",3,G25="X",4),0)} -> 1 | K25: MODELO DE GESTIÓN | N25: X | P25: SE ESTA FORTALECIENDO LA CULTURA, NO ESTA LEANTADO EL 100 DE LOS PROCEDIMEINTOS | Q25: {=IFERROR(_xlfn.IFS(L25="X",1,M25="X",2,N25="X",3,O25="X",4),0)} -> 3 | S25: NORMAS CORPORATIVAS VINCULANTES | Y25: {=IFERROR(_xlfn.IFS(T25="X",1,U25="X",2,V25="X",3,W25="X",4),0)} -> 0
C26: GESTIÓN DEL CAMBIO | F26: X | H26: SI SE PRACTICAN | I26: {=IFERROR(_xlfn.IFS(D26="X",1,E26="X",2,F26="X",3,G26="X",4),0)} -> 3 | K26: CUMPLIMIENTO DOCUMENTAL | M26: X | P26: HA AREAS QUE SE INVENTAN REGISTROS. MANEJO DE REGISTROS DIGITALES . REGISTROS FUERA DE; SISTEMAS. | Q26: {=IFERROR(_xlfn.IFS(L26="X",1,M26="X",2,N26="X",3,O26="X",4),0)} -> 2 | Y26: {=IFERROR(_xlfn.IFS(T26="X",1,U26="X",2,V26="X",3,W26="X",4),0)} -> 0
C27: TOMA DE DECISIONES | E27: X | H27: SE TOAMN DECISIONES POR JERARQUIAS | I27: {=IFERROR(_xlfn.IFS(D27="X",1,E27="X",2,F27="X",3,G27="X",4),0)} -> 2 | K27: ESTACIONES AUTOGESTIONADAS | L27: X | Q27: {=IFERROR(_xlfn.IFS(L27="X",1,M27="X",2,N27="X",3,O27="X",4),0)} -> 1 | Y27: {=IFERROR(_xlfn.IFS(T27="X",1,U27="X",2,V27="X",3,W27="X",4),0)} -> 0
C28: SANCIONES Y RECOMPENSAS | E28: X | H28: SOLO SANCIONES Y LA BSAE DE LICITUD ES EL RIT. ESTA EN PROCESO DE ACTUALIZACION | I28: {=IFERROR(_xlfn.IFS(D28="X",1,E28="X",2,F28="X",3,G28="X",4),0)} -> 2 | Q28: {=IFERROR(_xlfn.IFS(L28="X",1,M28="X",2,N28="X",3,O28="X",4),0)} -> 0 | Y28: {=IFERROR(_xlfn.IFS(T28="X",1,U28="X",2,V28="X",3,W28="X",4),0)} -> 0
I29: =AVERAGE(I15:I28) -> 2.3571429 | K29: =COUNTA(K15:K28) -> 13 | L29: =COUNTIFS(L15:L28,"x",L15:L28,"X")*1 -> 2 | M29: =COUNTIFS(M15:M28,"x",M15:M28,"X")*2 -> 6 | N29: =COUNTIFS(N15:N28,"x",N15:N28,"X")*3 -> 15 | O29: =COUNTIFS(O15:O28,"x",O15:O28,"X")*4 -> 8 | P29: =SUM(L29:O29)/K29 -> 2.3846154 | S29: =COUNTA(S15:S28) -> 11 | T29: =COUNTIFS(T15:T28,"x",T15:T28,"X")*1 -> 8 | U29: =COUNTIFS(U15:U28,"x",U15:U28,"X")*2 -> 2 | V29: =COUNTIFS(V15:V28,"x",V15:V28,"X")*3 -> 0 | W29: =COUNTIFS(W15:W28,"x",W15:W28,"X")*4 -> 0 | X29: =SUM(T29:W29)/S29 -> 0.90909091
D31: FÍSICAS - OPERATIVAS | L31: FÍSICAS - INFRAESTRUCTURA
E32: PSEUDO - PROFESIONAL | M32: PSEUDO - PROFESIONAL
D33: CAÓTICO (1) | E33: MEDIO BAJO (2) | F33: MEDIO ALTO (3) | G33: PROFESIONAL (4) | H33: COMENTARIO | L33: CAÓTICO (1) | M33: MEDIO BAJO (2) | N33: MEDIO ALTO (3) | O33: PROFESIONAL (4) | P33: COMENTARIO
C34: MODELO DE GESTIÓN - WORKING SYSTEM | D34: INEXISTENTE | E34: EMPÍRICO, POCA DOCUMENTACIÓN, TODO ES INFORMAL | F34: TAREAS DOCUMENTADAS, TÉCNICAS, MÉTODO SIN RIGUROSIDAD | G34: MODELO RIGUROSO y TÉCNICO | K34: MODELO DE GESTIÓN - WORKING SYSTEM | L34: INEXISTENTE | M34: EMPÍRICO, POCA DOCUMENTACIÓN, TODO ES INFORMAL | N34: TAREAS DOCUMENTADAS, TÉCNICAS, MÉTODO SIN RIGUROSIDAD | O34: MODELO RIGUROSO y TÉCNICO
C35: MAPEO PATD | D35: X | I35: {=IFERROR(_xlfn.IFS(D35="X",1,E35="X",2,F35="X",3,G35="X",4),0)} -> 1 | K35: CUARTO DE SERVIDORES | O35: X | Q35: {=IFERROR(_xlfn.IFS(L35="X",1,M35="X",2,N35="X",3,O35="X",4),0)} -> 4
C36: INTERACCIÓN TITULAR-RESPONSABLE | D36: X | I36: {=IFERROR(_xlfn.IFS(D36="X",1,E36="X",2,F36="X",3,G36="X",4),0)} -> 1 | K36: AVISOS INTERACCIÓN TITULAR-RESPO | L36: X | Q36: {=IFERROR(_xlfn.IFS(L36="X",1,M36="X",2,N36="X",3,O36="X",4),0)} -> 1
C37: REGISTROS PDP | D37: X | I37: {=IFERROR(_xlfn.IFS(D37="X",1,E37="X",2,F37="X",3,G37="X",4),0)} -> 1 | K37: SEGURIDAD FÍSICA PERIMETRAL | O37: X | Q37: {=IFERROR(_xlfn.IFS(L37="X",1,M37="X",2,N37="X",3,O37="X",4),0)} -> 4
C38: RUTINAS PDP | D38: X | I38: {=IFERROR(_xlfn.IFS(D38="X",1,E38="X",2,F38="X",3,G38="X",4),0)} -> 1 | K38: RUTINAS PDP | L38: X | Q38: {=IFERROR(_xlfn.IFS(L38="X",1,M38="X",2,N38="X",3,O38="X",4),0)} -> 1
C39: PROGRAMA COMPETENCIAS | D39: X | I39: {=IFERROR(_xlfn.IFS(D39="X",1,E39="X",2,F39="X",3,G39="X",4),0)} -> 1 | K39: MANTENIMIENTO GENERAL | N39: X | Q39: {=IFERROR(_xlfn.IFS(L39="X",1,M39="X",2,N39="X",3,O39="X",4),0)} -> 3
C40: PROGRAMA CONCIENCIACIÓN | D40: X | I40: {=IFERROR(_xlfn.IFS(D40="X",1,E40="X",2,F40="X",3,G40="X",4),0)} -> 1 | K40: CABLEADOS Y DISPOSITIVOS | O40: X | Q40: {=IFERROR(_xlfn.IFS(L40="X",1,M40="X",2,N40="X",3,O40="X",4),0)} -> 4
C41: CONTROL DE CAMBIOS | F41: X | I41: {=IFERROR(_xlfn.IFS(D41="X",1,E41="X",2,F41="X",3,G41="X",4),0)} -> 3 | K41: GESTIÓN DE INFRAESTRUCTURAS CRÍTICAS | O41: X | Q41: {=IFERROR(_xlfn.IFS(L41="X",1,M41="X",2,N41="X",3,O41="X",4),0)} -> 4
C42: PROGRAMA DE COMUNICACIÓN PDP | D42: X | I42: {=IFERROR(_xlfn.IFS(D42="X",1,E42="X",2,F42="X",3,G42="X",4),0)} -> 1 | K42: MANTENIMIENTO CARTELERAS PDP | L42: X | Q42: {=IFERROR(_xlfn.IFS(L42="X",1,M42="X",2,N42="X",3,O42="X",4),0)} -> 1
C43: =COUNTA(C35:C42) -> 8 | D43: =COUNTIFS(D35:D42,"x",D35:D42,"X")*1 -> 7 | E43: =COUNTIFS(E35:E42,"x",E35:E42,"X")*2 -> 0 | F43: =COUNTIFS(F35:F42,"x",F35:F42,"X")*3 -> 3 | G43: =COUNTIFS(G29:G42,"x",G29:G42,"X")*4 -> 0 | H43: =SUM(D43:G43)/C43 -> 1.25
D45: TÉCNICAS - COMPETENCIAS | L45: CRITERIOS DE EVALUACIÓN POR ÁREA DEL CONTEXTO INTERNO (Art. 47.2 LOPDP:2021)
...

Sheet ORGANIZATIVAS EET + PANSI 2026
D2: EVALUACIÓN DEL ESTADO DE LA TECNICA ÁREA ORGANIZATIVAS REQUISITO LOPDP:2021, ARTÍCULO 10.j
D6: CAÓTICO | E6: PSEUDO - PROFESIONAL | G6: PROFESIONAL
D7: 1 | E7: MEDIO BAJO 2 | F7: MEDIO ALTO 3 | G7: 4 | H7: COMENTARIOS
D8: INEXISTENTE | E8: MODELO DE GESTIÓN EMPÍRICO | F8: ORG. IFORMAL PREVALECE | G8: MODELO DE GESTIÓN TÉCNICO
C9: JERARQUIAS | F9: X | H9: EXISTE UN ORGANIGRAMA , EXISTEN INCOMPATIBILIDADES ENTRE CARGOS, NO EST[AN IDENTIFICADAS LAS OFICINAS TOPOLOGICAMENTE, LO BUENO ES QUE TODO ESTA ORGANIZADITO. | I9: {=IFERROR(_xlfn.IFS(D9="X",1,E9="X",2,F9="X",3,G9="X",4),0)} -> 3
B10: VULNERABILIDADES ORGANIZATIVAS | C10: ROLES | F10: X | H10: HAY QUE ACTULIZARLOS, HAY QUE REVISAR INCONSISTENCIAS, HAY COMITES CNSTITUIDOS POR RESOLUCI[ON. | I10: {=IFERROR(_xlfn.IFS(D10="X",1,E10="X",2,F10="X",3,G10="X",4),0)} -> 3
C11: DEFINICIÓN CONTEXTOS | D11: X | H11: EXISTE EL PLAN ESTRATEGICO, SIN EMBARGO, SE DEFINE LOS CONTEXTOS INTERNOS Y EXTERNOS MÁS NO UNA NOCIÓN EN RELACIÓN AL CONTEXTO DE PDP | I11: {=IFERROR(_xlfn.IFS(D11="X",1,E11="X",2,F11="X",3,G11="X",4),0)} -> 1
C12: IDENTIFICACIÓN 3ras PARTES | F12: X | H12: SIEXISTE ALGO DE BIA | I12: {=IFERROR(_xlfn.IFS(D12="X",1,E12="X",2,F12="X",3,G12="X",4),0)} -> 3
C13: IDENTIFICACIÓN ÁMBITOS | E13: X | H13: EXISTEN EN LOS MANUALES, NO ESTAN LOS DE MARKETING ESTAN LEVANTANDO PROCEDIMEINTOS, LOS VPN ESTAN BIEN PROCEDIMEINTADAS | I13: {=IFERROR(_xlfn.IFS(D13="X",1,E13="X",2,F13="X",3,G13="X",4),0)} -> 2
C14: GESTIÓN POR ÁMBITOS | F14: X | H14: ESTAN PROCEDIMENTADOS | I14: {=IFERROR(_xlfn.IFS(D14="X",1,E14="X",2,F14="X",3,G14="X",4),0)} -> 3
C15: ESTRATEGIA | F15: X | H15: EXISTE TODO EL MODELO, FALTAN LOS PRINCIPIOS | I15: {=IFERROR(_xlfn.IFS(D15="X",1,E15="X",2,F15="X",3,G15="X",4),0)} -> 3
C16: PLAN ESTRATÉGICO | D16: X | H16: ES INEXISTENTE PARA LOS MAS OPERATIVOS, NO ESTA SOCIALIZADO, NO SE SABE SI ESTA ASOCIADA LA NORMATIVA COMO | I16: {=IFERROR(_xlfn.IFS(D16="X",1,E16="X",2,F16="X",3,G16="X",4),0)} -> 1
C17: PLAN CONTINUIDAD | F17: X | H17: ACTUALIZAR PDP | I17: {=IFERROR(_xlfn.IFS(D17="X",1,E17="X",2,F17="X",3,G17="X",4),0)} -> 3
C18: DOCUMENTACIÓN GRC | F18: X | H18: ACTALIZAR LEY DE PDP | I18: {=IFERROR(_xlfn.IFS(D18="X",1,E18="X",2,F18="X",3,G18="X",4),0)} -> 3
C19: GESTIÓN TALENTO | D19: X | H19: NO EXISTE FORMALMENTE POR POSICION | I19: {=IFERROR(_xlfn.IFS(D19="X",1,E19="X",2,F19="X",3,G19="X",4),0)} -> 1
C20: GESTIÓN DEL CAMBIO | F20: X | H20: SI SE PRACTICAN | I20: {=IFERROR(_xlfn.IFS(D20="X",1,E20="X",2,F20="X",3,G20="X",4),0)} -> 3
C21: TOMA DE DECISIONES | E21: X | H21: SE TOAMN DECISIONES POR JERARQUIAS | I21: {=IFERROR(_xlfn.IFS(D21="X",1,E21="X",2,F21="X",3,G21="X",4),0)} -> 2
C22: SANCIONES Y RECOMPENSAS | E22: X | H22: SOLO SANCIONES Y LA BSAE DE LICITUD ES EL RIT. ESTA EN PROCESO DE ACTUALIZACION | I22: {=IFERROR(_xlfn.IFS(D22="X",1,E22="X",2,F22="X",3,G22="X",4),0)} -> 2
H23: ESTADO DE LA TÉCNICA | I23: =AVERAGEIF(I9:I22,"<>0") -> 2.3571429
D25: ADECUACIÓN DEL NIVEL DE SEGURIDAD (PANSI) ÁREA: ORGANIZATIVAS OBLIGACIÓN LOPDP:2021, ARTÍCULO 47.6 | I25: PANSI | K25: =AVERAGEIF(I32:I44,"<>0") -> 3
K28: REQUISITO ARTÍCULO 22.2 -RESOLUCIÓN 2025-0028-R (GARANTÍA DE INDEPENDENCIA PARA DPO) | U28: ESTATUS DEL COMPROMISO DE APLICABILIDAD
D29: CAÓTICO | E29: PSEUDO - PROFESIONAL | G29: PROFESIONAL
D30: 1 | E30: MEDIO BAJO 2 | F30: MEDIO ALTO 3 | G30: 4 | H30: ACCIONES MITIGADORAS | K30: RECURSOS NECESARIO | P30: COMPROMISOS DE APLICABILIDAD | U30: CUMPLIDO | V30: DEMORADO | W30: EN PROCESO
D31: INEXISTENTE | E31: MODELO DE GESTIÓN EMPÍRICO | F31: ORG. IFORMAL PREVALECE | G31: MODELO DE GESTIÓN TÉCNICO | H31: MEDIDAS, HERRAMIENTAS Y CONTROLES | K31: HUMANO | L31: TECNOLOGÍCO | M31: FINANCIERO | N31: INFRAESTRUCTURA | P31: FECHA PROBABLE | Q31: INVERSIÓN ESTIMADA | R31: COMENTARIOS
C32: ORGANIGRAMAS | I32: {=IFERROR(_xlfn.IFS(D32="X",1,E32="X",2,F32="X",3,G32="X",4),0)} -> 0
B33: VULNERABILIDADES ORGANIZATIVAS | C33: MANUAL DE ROLES Y FUNCIONES | I33: {=IFERROR(_xlfn.IFS(D33="X",1,E33="X",2,F33="X",3,G33="X",4),0)} -> 0
C34: DEFINICIÓN CONTEXTOS | F34: X | H34: accion que se incia con la personalización del SG-PDP que ya está contratado | I34: {=IFERROR(_xlfn.IFS(D34="X",1,E34="X",2,F34="X",3,G34="X",4),0)} -> 3 | K34: x | L34: x | M34: x | N34: x | P34: 1ra semana febrero | R34: el recurso financiero ya está otorgado debido a que se contrato el proyecto PDP-360°
C35: IDENTIFICACIÓN 3ras PARTES | F35: X | H35: accion que se incia con la personalización del SG-PDP que ya está contratado | I35: {=IFERROR(_xlfn.IFS(D35="X",1,E35="X",2,F35="X",3,G35="X",4),0)} -> 3
C36: IDENTIFICACIÓN ÁMBITOS | I36: {=IFERROR(_xlfn.IFS(D36="X",1,E36="X",2,F36="X",3,G36="X",4),0)} -> 0
C37: ESTRATEGIA | I37: {=IFERROR(_xlfn.IFS(D37="X",1,E37="X",2,F37="X",3,G37="X",4),0)} -> 0
C38: PLAN ESTRATÉGICO | F38: X | H38: Socializar el Plan Estratégico con el Personal y realizar adecuaciones con los objetivos de PDP | I38: {=IFERROR(_xlfn.IFS(D38="X",1,E38="X",2,F38="X",3,G38="X",4),0)} -> 3 | K38: x | P38: 1ra semana febrero | R38: lo debe revisar el delegado de protección de datos
C39: PLAN CONTINUIDAD | F39: X | H39: se debe incluir como atender la intermitencias en caso de PDP | I39: {=IFERROR(_xlfn.IFS(D39="X",1,E39="X",2,F39="X",3,G39="X",4),0)} -> 3 | K39: x | M39: x | P39: 3ra semana febrero | R39: financieros para robustecer acciones, medidas y herramientas de ser necesaro. Todavia no se tiene un estimado de la posible inversión. El DPD y el equipo interno deben tener un presupuesto base , para final de febrero. 1 existe normativa de la SEPS en las resoluciones 116 de riesgo operativo 002 de Seguridad de la información y la 009 de caales electrónicos que atienden aspectos sobre crisis ointermitencias. 2. se deden incluir acciones en terceras partes y sede elementos como : ejercicio de derechos
C40: DOCUMENTACIÓN GRC | F40: X | H40: actalizar para políticas, procedimientos e instructivos | I40: {=IFERROR(_xlfn.IFS(D40="X",1,E40="X",2,F40="X",3,G40="X",4),0)} -> 3
C41: GESTIÓN TALENTO | F41: X | H41: Priorizar la formación del líder PDP antes de finalizar el segundo trimestre 2026 | I41: {=IFERROR(_xlfn.IFS(D41="X",1,E41="X",2,F41="X",3,G41="X",4),0)} -> 3 | K41: x | M41: x | P41: final bril 2026 | R41: deberia iniciar en Marzo. Probablemento EleviGo
C42: GESTIÓN DEL CAMBIO | I42: {=IFERROR(_xlfn.IFS(D42="X",1,E42="X",2,F42="X",3,G42="X",4),0)} -> 0
C43: TOMA DE DECISIONES | I43: {=IFERROR(_xlfn.IFS(D43="X",1,E43="X",2,F43="X",3,G43="X",4),0)} -> 0
C44: SANCIONES Y RECOMPENSAS | F44: X | H44: revisar como incluir tipos de recompensas adicional al manual de sanciones | I44: {=IFERROR(_xlfn.IFS(D44="X",1,E44="X",2,F44="X",3,G44="X",4),0)} -> 3 | K44: x | P44: final febrero 2026

Sheet ADMINISTRATI EET + PANSI 2026
D2: EVALUACIÓN DEL ESTADO DE LA TECNICA ÁREA: ADMINISTRATIVAS REQUISITO LOPDP:2021, ARTÍCULO 10.j
D6: CAÓTICO | E6: PSEUDO - PROFESIONAL | G6: PROFESIONAL
D7: 1 | E7: MEDIO BAJO 2 | F7: MEDIO ALTO 3 | G7: 4 | H7: COMENTARIOS
D8: INEXISTENTE | E8: MODELO DE GESTIÓN EMPÍRICO | F8: ORG. IFORMAL PREVALECE | G8: MODELO DE GESTIÓN TÉCNICO
C9: SANCIONES Y RECOMPENSAS | F9: X | H9: SE DEBE ACTUALIZAR, NO STA NORMADO LA PARTE DE RECOMPENSAS PERO SI HAY ALGUNOS INCENTIVOS | I9: {=IFERROR(_xlfn.IFS(D9="X",1,E9="X",2,F9="X",3,G9="X",4),0)} -> 3
B10: VULNERABILIDADES ADMINISTRATIVAS | C10: EVALUACIONES INTERNAS | G10: X | H10: EXISTE TODAS LAS RESOLUCIONES QUE IMPONE LA SEPD., EXITE RESOLUCION 360 POR APROBACIÓN | I10: {=IFERROR(_xlfn.IFS(D10="X",1,E10="X",2,F10="X",3,G10="X",4),0)} -> 4
C11: EVALUACIÓN 3ras PARTES | F11: X | H11: SOLO LOS DE LOS QUE EXIGGE LA UAFE | I11: {=IFERROR(_xlfn.IFS(D11="X",1,E11="X",2,F11="X",3,G11="X",4),0)} -> 3
C12: INGRESOS Y DESVINCULACIÓN | E12: X | H12: NO SE CUMPLE DE MANERA RIGUROSA. | I12: {=IFERROR(_xlfn.IFS(D12="X",1,E12="X",2,F12="X",3,G12="X",4),0)} -> 2
C13: MEJORA CONTINUA Y RESILIENCIA | E13: X | H13: INTENTAN IMPLEMENTAR LAS BUENAS PRÁCTICAS DE LA ISO 9001:2015, SIN EMBARGO, NO EXISTE UNA METODOLOGÍA QUE DEFINA LA MEJORA CONTINUA | I13: {=IFERROR(_xlfn.IFS(D13="X",1,E13="X",2,F13="X",3,G13="X",4),0)} -> 2
C14: GESTIÓN DE INDICADORES | F14: X | H14: SOLO LOS QUE PIDE LA NORMA | I14: {=IFERROR(_xlfn.IFS(D14="X",1,E14="X",2,F14="X",3,G14="X",4),0)} -> 3
C15: PLAN AUDITORÍAS INTERNAS | G15: X | H15: SOLO LOS QUE DEFINE AREA DE AUDITORIA INTERNA | I15: {=IFERROR(_xlfn.IFS(D15="X",1,E15="X",2,F15="X",3,G15="X",4),0)} -> 4
C16: PLAN AUDITORÍAS 3ras PARTES | D16: X | H16: SOLO SE MANEJA LAS AUDITORÍAS FINANCIERAS TANTO INTERNAS COMO EXTERNAS | I16: {=IFERROR(_xlfn.IFS(D16="X",1,E16="X",2,F16="X",3,G16="X",4),0)} -> 1
C17: PLAN DE SIMULACROS | I17: {=IFERROR(_xlfn.IFS(D17="X",1,E17="X",2,F17="X",3,G17="X",4),0)} -> 0
C18: SIMULACROS 3ras PARTES | F18: X | H18: INCLUYE LOS DE SEGURIDAD DE LA INFORMACI[ON | I18: {=IFERROR(_xlfn.IFS(D18="X",1,E18="X",2,F18="X",3,G18="X",4),0)} -> 3
C19: MODELO DE GESTIÓN | F19: X | H19: SE ESTA FORTALECIENDO LA CULTURA, NO ESTA LEANTADO EL 100 DE LOS PROCEDIMEINTOS | I19: {=IFERROR(_xlfn.IFS(D19="X",1,E19="X",2,F19="X",3,G19="X",4),0)} -> 3
C20: CUMPLIMIENTO DOCUMENTAL | E20: X | H20: HA AREAS QUE SE INVENTAN REGISTROS. MANEJO DE REGISTROS DIGITALES . REGISTROS FUERA DE; SISTEMAS. | I20: {=IFERROR(_xlfn.IFS(D20="X",1,E20="X",2,F20="X",3,G20="X",4),0)} -> 2
C21: ESTACIONES AUTOGESTIONADAS | D21: X | I21: {=IFERROR(_xlfn.IFS(D21="X",1,E21="X",2,F21="X",3,G21="X",4),0)} -> 1
I22: {=IFERROR(_xlfn.IFS(D22="X",1,E22="X",2,F22="X",3,G22="X",4),0)} -> 0
H23: ESTADO DE LA TÉCNICA | I23: =AVERAGEIF(I9:I22,"<>0") -> 2.5833333
D25: ADECUACIÓN DEL NIVEL DE SEGURIDAD (PANSI) ÁREA: ADMINISTRATIVAS OBLIGACIÓN LOPDP:2021, ARTÍCULO 47.6 | I25: PANSI | K25: =AVERAGEIF(I32:I45,"<>0") -> 3
K28: REQUISITO ARTÍCULO 22.2 -RESOLUCIÓN 2025-0028-R (GARANTÍA DE INDEPENDENCIA PARA DPO) | U28: ESTATUS DEL COMPROMISO DE APLICABILIDAD
D29: CAÓTICO | E29: PSEUDO - PROFESIONAL | G29: PROFESIONAL
D30: 1 | E30: MEDIO BAJO 2 | F30: MEDIO ALTO 3 | G30: 4 | H30: ACCIONES MITIGADORAS | K30: RECURSOS NECESARIO | P30: COMPROMISOS DE APLICABILIDAD | U30: CUMPLIDO | V30: DEMORADO | W30: EN PROCESO
D31: INEXISTENTE | E31: MODELO DE GESTIÓN EMPÍRICO | F31: ORG. IFORMAL PREVALECE | G31: MODELO DE GESTIÓN TÉCNICO | H31: MEDIDAS, HERRAMIENTAS Y CONTROLES | K31: HUMANO | L31: TECNOLOGÍCO | M31: FINANCIERO | N31: INFRAESTRUCTURA | P31: FECHA PROBABLE | Q31: INVERSIÓN ESTIMADA | R31: COMENTARIOS
C32: SANCIONES Y RECOMPENSAS | I32: {=IFERROR(_xlfn.IFS(D32="X",1,E32="X",2,F32="X",3,G32="X",4),0)} -> 0
B33: VULNERABILIDADES ADMINISTRATIVAS | C33: EVALUACIONES INTERNAS | I33: {=IFERROR(_xlfn.IFS(D33="X",1,E33="X",2,F33="X",3,G33="X",4),0)} -> 0
C34: EVALUACIÓN 3ras PARTES | F34: X | H34: definir terceras partes críticas y el costo de posibles auditorias de terceras partes | I34: {=IFERROR(_xlfn.IFS(D34="X",1,E34="X",2,F34="X",3,G34="X",4),0)} -> 3 | K34: x | M34: x | P34: 46174 | R34: En la fase implantación se inicia con el plan de auditorías de terceras partes críticas. Las terceras partes que ofrecen servicios de plataformas o softwares deben obigatoriamente por el articulo 42 de la LOPDP:2021 presentar una Evaluación de Impacto. Si no la tienen en la revisión del contrato se debe colocar la rutina de PDP y una fecha en la cual deben entregar la evaluación de impacto "positiva".
C35: INGRESOS Y DESVINCULACIÓN | F35: X | H35: Se revisarán y actualizarán los procedimientos , se realizará o incluirán dentro del programa de conscienciación | I35: {=IFERROR(_xlfn.IFS(D35="X",1,E35="X",2,F35="X",3,G35="X",4),0)} -> 3 | K35: x | P35: 46054
C36: MEJORA CONTINUA Y RESILIENCIA | F36: X | H36: se activa a final de marz 2026 con la implantación de la dcumentación del SG-PDP | I36: {=IFERROR(_xlfn.IFS(D36="X",1,E36="X",2,F36="X",3,G36="X",4),0)} -> 3 | K36: x | L36: x | P36: 46113 | R36: la inversión está hecha con la conratación PDP-360°
C37: GESTIÓN DE INDICADORES | I37: {=IFERROR(_xlfn.IFS(D37="X",1,E37="X",2,F37="X",3,G37="X",4),0)} -> 0
C38: PLAN AUDITORÍAS INTERNAS | F38: X | H38: se activa a final de marz 2026 con la implantación de la dcumentación del SG-PDP | I38: {=IFERROR(_xlfn.IFS(D38="X",1,E38="X",2,F38="X",3,G38="X",4),0)} -> 3 | K38: x | L38: x | P38: 46113 | R38: la inversión está hecha con la conratación PDP-360°. Hay que revisar el plan de auditoría interna que ya está aprobado para validar si estan incluyendo las auditorías del SG-PDP
C39: PLAN AUDITOÍAS 3ras PARTES | F39: X | H39: se activa en agosto 2026 luego de que el SG-PDP este validado | I39: {=IFERROR(_xlfn.IFS(D39="X",1,E39="X",2,F39="X",3,G39="X",4),0)} -> 3 | K39: x | L39: x | M39: x | P39: 46235 | R39: se deben definir las terceras partes criticas y evaluar la disponibilidad de presupuesto para dar inicio a esta acción mitigadora del riesgo que representan la 3ra partes
C40: PLAN DE SIMULACROS | I40: {=IFERROR(_xlfn.IFS(D40="X",1,E40="X",2,F40="X",3,G40="X",4),0)} -> 0
C41: SIMULACROS 3ras PARTES | I41: {=IFERROR(_xlfn.IFS(D41="X",1,E41="X",2,F41="X",3,G41="X",4),0)} -> 0
C42: MODELO DE GESTIÓN | I42: {=IFERROR(_xlfn.IFS(D42="X",1,E42="X",2,F42="X",3,G42="X",4),0)} -> 0
C43: CUMPLIMIENTO DOCUMENTAL | F43: X | H43: esto se aegura ya que es la responsabilidad del líder de proyecto supervisado por el delegado de protección de datos | I43: {=IFERROR(_xlfn.IFS(D43="X",1,E43="X",2,F43="X",3,G43="X",4),0)} -> 3 | K43: x | P43: 46054 | R43: la inversión está hecha con la conratación PDP-360°
C44: ESTACIONES AUTOGESTIONADAS | F44: X | H44: Nacen o se identifican en la personalización de la documentación del SG-PDP contratado | I44: {=IFERROR(_xlfn.IFS(D44="X",1,E44="X",2,F44="X",3,G44="X",4),0)} -> 3 | K44: x | P44: 46082 | R44: la inversión está hecha con la conratación PDP-360°
I45: {=IFERROR(_xlfn.IFS(D45="X",1,E45="X",2,F45="X",3,G45="X",4),0)} -> 0

Sheet JURÍDICAS EET + PANSI 2026
D2: EVALUACIÓN DEL ESTADO DE LA TECNICA ÁREA: JURÍDICAS REQUISITO LOPDP:2021, ARTÍCULO 10.j
D6: CAÓTICO | E6: PSEUDO - PROFESIONAL | G6: PROFESIONAL
D7: 1 | E7: MEDIO BAJO 2 | F7: MEDIO ALTO 3 | G7: 4 | H7: COMENTARIOS
D8: INEXISTENTE | E8: MODELO DE GESTIÓN EMPÍRICO | F8: ORG. IFORMAL PREVALECE | G8: MODELO DE GESTIÓN TÉCNICO
C9: COMUNICADOS | D9: X | I9: {=IFERROR(_xlfn.IFS(D9="X",1,E9="X",2,F9="X",3,G9="X",4),0)} -> 1
B10: VULNERABILIDADES JURÍDICAS | C10: CONTRATOS | E10: X | H10: EXISTE UN RESPONSABLE JURÍDICO, SIN EMBARGO, NO SE CONSIDERAN LAS CLAUSULAS EMITIDAS POR LA SPDP | I10: {=IFERROR(_xlfn.IFS(D10="X",1,E10="X",2,F10="X",3,G10="X",4),0)} -> 2
C11: RESPUESTAS | D11: X | I11: {=IFERROR(_xlfn.IFS(D11="X",1,E11="X",2,F11="X",3,G11="X",4),0)} -> 1
C12: REGISTROS ANTE SPDP | D12: X | I12: {=IFERROR(_xlfn.IFS(D12="X",1,E12="X",2,F12="X",3,G12="X",4),0)} -> 1
C13: EVALUACIONES JURÍDICAS | D13: X | I13: {=IFERROR(_xlfn.IFS(D13="X",1,E13="X",2,F13="X",3,G13="X",4),0)} -> 1
C14: GESTIÓN POR ÁMBITOS | D14: X | I14: {=IFERROR(_xlfn.IFS(D14="X",1,E14="X",2,F14="X",3,G14="X",4),0)} -> 1
C15: POLÍTICAS MARCO LEGAL VIGENTE | D15: X | I15: {=IFERROR(_xlfn.IFS(D15="X",1,E15="X",2,F15="X",3,G15="X",4),0)} -> 1
C16: EJERCICIO DE DERECHOS | D16: X | I16: {=IFERROR(_xlfn.IFS(D16="X",1,E16="X",2,F16="X",3,G16="X",4),0)} -> 1
C17: GARANTIAS ADECUADAS | I17: {=IFERROR(_xlfn.IFS(D17="X",1,E17="X",2,F17="X",3,G17="X",4),0)} -> 0
C18: DOCUMENTACIÓN GRC | D18: X | I18: {=IFERROR(_xlfn.IFS(D18="X",1,E18="X",2,F18="X",3,G18="X",4),0)} -> 1
C19: NORMAS CORPORATIVAS VINCULANTES | I19: {=IFERROR(_xlfn.IFS(D19="X",1,E19="X",2,F19="X",3,G19="X",4),0)} -> 0
I20: {=IFERROR(_xlfn.IFS(D20="X",1,E20="X",2,F20="X",3,G20="X",4),0)} -> 0
H21: ESTADO DE LA TÉCNICA | I21: =AVERAGEIF(I9:I20,"<>0") -> 1.1111111
D23: ADECUACIÓN DEL NIVEL DE SEGURIDAD (PANSI) ÁREA: JURÍDICAS OBLIGACIÓN LOPDP:2021, ARTÍCULO 47.6 | I23: PANSI | K23: =AVERAGEIF(I30:I41,"<>0") -> 3.1111111
K26: REQUISITO ARTÍCULO 22.2 -RESOLUCIÓN 2025-0028-R (GARANTÍA DE INDEPENDENCIA PARA DPO) | U26: ESTATUS DEL COMPROMISO DE APLICABILIDAD
D27: CAÓTICO | E27: PSEUDO - PROFESIONAL | G27: PROFESIONAL
D28: 1 | E28: MEDIO BAJO 2 | F28: MEDIO ALTO 3 | G28: 4 | H28: ACCIONES MITIGADORAS | K28: RECURSOS NECESARIO | P28: COMPROMISOS DE APLICABILIDAD | U28: CUMPLIDO | V28: DEMORADO | W28: EN PROCESO
D29: INEXISTENTE | E29: MODELO DE GESTIÓN EMPÍRICO | F29: ORG. IFORMAL PREVALECE | G29: MODELO DE GESTIÓN TÉCNICO | H29: MEDIDAS, HERRAMIENTAS Y CONTROLES | K29: HUMANO | L29: TECNOLOGÍCO | M29: FINANCIERO | N29: INFRAESTRUCTURA | P29: FECHA PROBABLE | Q29: INVERSIÓN ESTIMADA | R29: COMENTARIOS
C30: COMUNICADOS | F30: X | H30: Todas estas calificaciones tendrán como mínimo 3 puntos ya que la personalización de la documentación del SG-PDP contratado permitirá que todas sean atendidas y actualizadas. | I30: {=IFERROR(_xlfn.IFS(D30="X",1,E30="X",2,F30="X",3,G30="X",4),0)} -> 3 | K30: x | M30: x | P30: 46082 | R30: la inversión se srealizó con la contratación de PDP-360°
B31: VULNERABILIDADES JURÍDICAS | C31: CONTRATOS | F31: X | I31: {=IFERROR(_xlfn.IFS(D31="X",1,E31="X",2,F31="X",3,G31="X",4),0)} -> 3
C32: RESPUESTAS | F32: X | I32: {=IFERROR(_xlfn.IFS(D32="X",1,E32="X",2,F32="X",3,G32="X",4),0)} -> 3
C33: REGISTROS ANTE SPDP | G33: X | I33: {=IFERROR(_xlfn.IFS(D33="X",1,E33="X",2,F33="X",3,G33="X",4),0)} -> 4
C34: EVALUACIONES JURÍDICAS | F34: X | I34: {=IFERROR(_xlfn.IFS(D34="X",1,E34="X",2,F34="X",3,G34="X",4),0)} -> 3
C35: GESTIÓN POR ÁMBITOS | F35: X | I35: {=IFERROR(_xlfn.IFS(D35="X",1,E35="X",2,F35="X",3,G35="X",4),0)} -> 3
C36: POLÍTICAS MARCO LEGAL VIGENTE | F36: X | I36: {=IFERROR(_xlfn.IFS(D36="X",1,E36="X",2,F36="X",3,G36="X",4),0)} -> 3
C37: EJERCICIO DE DERECHOS | F37: X | I37: {=IFERROR(_xlfn.IFS(D37="X",1,E37="X",2,F37="X",3,G37="X",4),0)} -> 3
C38: GARANTIAS ADECUADAS | I38: {=IFERROR(_xlfn.IFS(D38="X",1,E38="X",2,F38="X",3,G38="X",4),0)} -> 0
C39: DOCUMENTACIÓN GRC | F39: X | I39: {=IFERROR(_xlfn.IFS(D39="X",1,E39="X",2,F39="X",3,G39="X",4),0)} -> 3
C40: NORMAS CORPORATIVAS VINCULANTES | I40: {=IFERROR(_xlfn.IFS(D40="X",1,E40="X",2,F40="X",3,G40="X",4),0)} -> 0
I41: {=IFERROR(_xlfn.IFS(D41="X",1,E41="X",2,F41="X",3,G41="X",4),0)} -> 0

Sheet FÍSICA - OPER  EET + PANSI 2026
D2: EVALUACIÓN DEL ESTADO DE LA TECNICA ÁREA: FÍSICA-OPERATIVAS REQUISITO LOPDP:2021, ARTÍCULO 10.j
D6: CAÓTICO | E6: PSEUDO - PROFESIONAL | G6: PROFESIONAL
D7: 1 | E7: MEDIO BAJO 2 | F7: MEDIO ALTO 3 | G7: 4 | H7: COMENTARIOS
D8: INEXISTENTE | E8: MODELO DE GESTIÓN EMPÍRICO | F8: ORG. IFORMAL PREVALECE | G8: MODELO DE GESTIÓN TÉCNICO
B9: VULNERABILIDADES FÍSICAS - OPERATIVAS | C9: MAPEO PATD | D9: X | I9: {=IFERROR(_xlfn.IFS(D9="X",1,E9="X",2,F9="X",3,G9="X",4),0)} -> 1
C10: INTERACCIÓN TITULAR-RESPONSABLE | D10: X | I10: {=IFERROR(_xlfn.IFS(D10="X",1,E10="X",2,F10="X",3,G10="X",4),0)} -> 1
C11: REGISTROS PDP | D11: X | I11: {=IFERROR(_xlfn.IFS(D11="X",1,E11="X",2,F11="X",3,G11="X",4),0)} -> 1
C12: RUTINAS PDP | D12: X | I12: {=IFERROR(_xlfn.IFS(D12="X",1,E12="X",2,F12="X",3,G12="X",4),0)} -> 1
C13: PROGRAMA COMPETENCIAS | D13: X | I13: {=IFERROR(_xlfn.IFS(D13="X",1,E13="X",2,F13="X",3,G13="X",4),0)} -> 1
C14: PROGRAMA CONCIENCIACIÓN | D14: X | I14: {=IFERROR(_xlfn.IFS(D14="X",1,E14="X",2,F14="X",3,G14="X",4),0)} -> 1
C15: CONTROL DE CAMBIOS | F15: X | H15: MANTIENEN BITÁCORAS DE CONTROL DE CAMBIOS | I15: {=IFERROR(_xlfn.IFS(D15="X",1,E15="X",2,F15="X",3,G15="X",4),0)} -> 3
C16: PROGRAMA DE COMUNICACIÓN PDP | D16: X | I16: {=IFERROR(_xlfn.IFS(D16="X",1,E16="X",2,F16="X",3,G16="X",4),0)} -> 1
H18: ESTADO DE LA TÉCNICA | I18: =AVERAGEIF(I9:I17,"<>0") -> 1.25
D20: ADECUACIÓN DEL NIVEL DE SEGURIDAD (PANSI) ÁREA: FÍSICA-OPERATIVAS OBLIGACIÓN LOPDP:2021, ARTÍCULO 47.6 | I20: PANSI | K20: =AVERAGEIF(I27:I34,"<>0") -> 3
K23: REQUISITO ARTÍCULO 22.2 -RESOLUCIÓN 2025-0028-R (GARANTÍA DE INDEPENDENCIA PARA DPO) | U23: ESTATUS DEL COMPROMISO DE APLICABILIDAD
D24: CAÓTICO | E24: PSEUDO - PROFESIONAL | G24: PROFESIONAL
D25: 1 | E25: MEDIO BAJO 2 | F25: MEDIO ALTO 3 | G25: 4 | H25: ACCIONES MITIGADORAS | K25: RECURSOS NECESARIO | P25: COMPROMISOS DE APLICABILIDAD | U25: CUMPLIDO | V25: DEMORADO | W25: EN PROCESO
D26: INEXISTENTE | E26: MODELO DE GESTIÓN EMPÍRICO | F26: ORG. IFORMAL PREVALECE | G26: MODELO DE GESTIÓN TÉCNICO | H26: MEDIDAS, HERRAMIENTAS Y CONTROLES | K26: HUMANO | L26: TECNOLOGÍCO | M26: FINANCIERO | N26: INFRAESTRUCTURA | P26: FECHA PROBABLE | Q26: INVERSIÓN ESTIMADA | R26: COMENTARIOS
B27: VULNERABILIDADES FÍSICAS - OPERATIVAS | C27: MAPEO PATD | F27: X | I27: {=IFERROR(_xlfn.IFS(D27="X",1,E27="X",2,F27="X",3,G27="X",4),0)} -> 3
C28: INTERACCIÓN TITULAR-RESPONSABLE | F28: X | I28: {=IFERROR(_xlfn.IFS(D28="X",1,E28="X",2,F28="X",3,G28="X",4),0)} -> 3
C29: REGISTROS PDP | F29: X | H29: TODO SE REALIZARÁ DESDE LA PLATAFORMA . SE DEBE CONTACTAR AL PROVEEDOR DE LA PLATAFORMA YA QUE SE DEBE VALIDAR QUE TENGAN ESQUEMA DE PDP. | I29: {=IFERROR(_xlfn.IFS(D29="X",1,E29="X",2,F29="X",3,G29="X",4),0)} -> 3 | K29: X | L29: X | P29: 46082
C30: RUTINAS PDP | F30: X | H30: se desarrollarán en cada PATD | I30: {=IFERROR(_xlfn.IFS(D30="X",1,E30="X",2,F30="X",3,G30="X",4),0)} -> 3 | K30: x | M30: x | P30: 46082 | R30: los recursos ya fueron asignados con la contratacióndel PDP-360°
C31: PROGRAMA COMPETENCIAS | F31: X | H31: Se debe iniciar en Arbril 2026 con la implam¿ntación de la documentación del PDP-360° | I31: {=IFERROR(_xlfn.IFS(D31="X",1,E31="X",2,F31="X",3,G31="X",4),0)} -> 3 | K31: x | L31: x | M31: x | P31: 46113 | R31: los recursos ya fueron asignados con la contratacióndel PDP-360°
C32: PROGRAMA CONCIENCIACIÓN | F32: X | H32: Se debe iniciar en Arbril 2026 con la implam¿ntación de la documentación del PDP-360° | I32: {=IFERROR(_xlfn.IFS(D32="X",1,E32="X",2,F32="X",3,G32="X",4),0)} -> 3 | K32: x | L32: x | M32: x | P32: 46113 | R32: los recursos ya fueron asignados con la contratacióndel PDP-360°
C33: CONTROL DE CAMBIOS | F33: X | H33: Se debe iniciar en Arbril 2026 con la implam¿ntación de la documentación del PDP-360° | I33: {=IFERROR(_xlfn.IFS(D33="X",1,E33="X",2,F33="X",3,G33="X",4),0)} -> 3 | K33: x | L33: x | M33: x | P33: 46113 | R33: los recursos ya fueron asignados con la contratacióndel PDP-360°
C34: PROGRAMA DE COMUNICACIÓN PDP | F34: X | H34: Se debe iniciar en Arbril 2026 con la implam¿ntación de la documentación del PDP-360° | I34: {=IFERROR(_xlfn.IFS(D34="X",1,E34="X",2,F34="X",3,G34="X",4),0)} -> 3 | K34: x | L34: x | M34: x | P34: 46113 | R34: los recursos ya fueron asignados con la contratacióndel PDP-360°

Sheet FÍSICAS - INFRSTRA  EET + PANSI
D2: EVALUACIÓN DEL ESTADO DE LA TECNICA ÁREA: FÍSICA-INFRAESTRUCTURA REQUISITO LOPDP:2021, ARTÍCULO 10.j
D6: CAÓTICO | E6: PSEUDO - PROFESIONAL | G6: PROFESIONAL
D7: 1 | E7: MEDIO BAJO 2 | F7: MEDIO ALTO 3 | G7: 4 | H7: COMENTARIOS
D8: INEXISTENTE | E8: MODELO DE GESTIÓN EMPÍRICO | F8: ORG. IFORMAL PREVALECE | G8: MODELO DE GESTIÓN TÉCNICO
B9: VULNERABILIDADES FÍSICAS - INFRAESTRUCTURA | C9: CUARTO DE SERVIDORES | G9: X | H9: CUMPLEN CON LOS REQUISITOS PARA UN DATA CENTER | I9: {=IFERROR(_xlfn.IFS(D9="X",1,E9="X",2,F9="X",3,G9="X",4),0)} -> 4
C10: AVISOS INTERACCIÓN TITULAR-RESPO | D10: X | I10: {=IFERROR(_xlfn.IFS(D10="X",1,E10="X",2,F10="X",3,G10="X",4),0)} -> 1
C11: SEGURIDAD FÍSICA PERIMETRAL | G11: X | H11: CUENTAN CON LO ESTABLECIDO EN LA NORMA DE SEGURIDADES FÍSICAS Y ELECTRÓNICAS SEGÚN LA RESOLUCIÓN 021-2018 DE LA SEPS | I11: {=IFERROR(_xlfn.IFS(D11="X",1,E11="X",2,F11="X",3,G11="X",4),0)} -> 4
C12: RUTINAS PDP | D12: X | I12: {=IFERROR(_xlfn.IFS(D12="X",1,E12="X",2,F12="X",3,G12="X",4),0)} -> 1
C13: MANTENIMIENTO GENERAL | F13: X | H13: LO REALIZAN DE MANERA ANUAL, SIN EMBARGO, NO SE ENCUENTRA EN UN PLAN OPERATIVO ANUAL | I13: {=IFERROR(_xlfn.IFS(D13="X",1,E13="X",2,F13="X",3,G13="X",4),0)} -> 3
C14: CABLEADOS Y DISPOSITIVOS | G14: X | H14: CUENTAN CON LO ESTABLECIDO EN LA NORMA DE SEGURIDADES FÍSICAS Y ELECTRÓNICAS SEGÚN LA RESOLUCIÓN 021-2018 DE LA SEPS | I14: {=IFERROR(_xlfn.IFS(D14="X",1,E14="X",2,F14="X",3,G14="X",4),0)} -> 4
C15: GESTIÓN DE INFRAESTRUCTURAS CRÍTICAS | G15: X | H15: CUENTAN CON LO ESTABLECIDO EN LA NORMA DE SEGURIDADES FÍSICAS Y ELECTRÓNICAS SEGÚN LA RESOLUCIÓN 021-2018 DE LA SEPS | I15: {=IFERROR(_xlfn.IFS(D15="X",1,E15="X",2,F15="X",3,G15="X",4),0)} -> 4
C16: MANTENIMIENTO CARTELERAS PDP | D16: X | I16: {=IFERROR(_xlfn.IFS(D16="X",1,E16="X",2,F16="X",3,G16="X",4),0)} -> 1
H18: ESTADO DE LA TÉCNICA | I18: =AVERAGEIF(I9:I17,"<>0") -> 2.75
D20: ADECUACIÓN DEL NIVEL DE SEGURIDAD (PANSI) ÁREA: FÍSICA-INFRAESTRUCTURA OBLIGACIÓN LOPDP:2021, ARTÍCULO 47.6 | I20: PANSI | K20: =AVERAGEIF(I27:I34,"<>0") -> 3
K23: REQUISITO ARTÍCULO 22.2 -RESOLUCIÓN 2025-0028-R (GARANTÍA DE INDEPENDENCIA PARA DPO) | U23: ESTATUS DEL COMPROMISO DE APLICABILIDAD
D24: CAÓTICO | E24: PSEUDO - PROFESIONAL | G24: PROFESIONAL
D25: 1 | E25: MEDIO BAJO 2 | F25: MEDIO ALTO 3 | G25: 4 | H25: ACCIONES MITIGADORAS | K25: RECURSOS NECESARIO | P25: COMPROMISOS DE APLICABILIDAD | U25: CUMPLIDO | V25: DEMORADO | W25: EN PROCESO
D26: INEXISTENTE | E26: MODELO DE GESTIÓN EMPÍRICO | F26: ORG. IFORMAL PREVALECE | G26: MODELO DE GESTIÓN TÉCNICO | H26: MEDIDAS, HERRAMIENTAS Y CONTROLES | K26: HUMANO | L26: TECNOLOGÍCO | M26: FINANCIERO | N26: INFRAESTRUCTURA | P26: FECHA PROBABLE | Q26: INVERSIÓN ESTIMADA | R26: COMENTARIOS
B27: VULNERABILIDADES FÍSICAS - INFRAESTRUCTURA | C27: CUARTO DE SERVIDORES | I27: {=IFERROR(_xlfn.IFS(D27="X",1,E27="X",2,F27="X",3,G27="X",4),0)} -> 0
C28: AVISOS INTERACCIÓN TITULAR-RESPO | F28: X | H28: Se debe iniciar en Arbril 2026 con la implam¿ntación de la documentación del PDP-360° | I28: {=IFERROR(_xlfn.IFS(D28="X",1,E28="X",2,F28="X",3,G28="X",4),0)} -> 3 | K28: x | L28: x | M28: x | P28: 46113 | R28: los recursos ya fueron asignados con la contratacióndel PDP-360°
C29: SEGURIDAD FÍSICA PERIMETRAL | I29: {=IFERROR(_xlfn.IFS(D29="X",1,E29="X",2,F29="X",3,G29="X",4),0)} -> 0
C30: RUTINAS PDP | F30: X | H30: Se debe iniciar en Arbril 2026 con la implam¿ntación de la documentación del PDP-360° | I30: {=IFERROR(_xlfn.IFS(D30="X",1,E30="X",2,F30="X",3,G30="X",4),0)} -> 3 | K30: x | L30: x | M30: x | P30: 46113 | R30: los recursos ya fueron asignados con la contratacióndel PDP-360°
C31: MANTENIMIENTO GENERAL | I31: {=IFERROR(_xlfn.IFS(D31="X",1,E31="X",2,F31="X",3,G31="X",4),0)} -> 0
C32: CABLEADOS Y DISPOSITIVOS | I32: {=IFERROR(_xlfn.IFS(D32="X",1,E32="X",2,F32="X",3,G32="X",4),0)} -> 0
C33: GESTIÓN DE INFRAESTRUCTURAS CRÍTICAS | I33: {=IFERROR(_xlfn.IFS(D33="X",1,E33="X",2,F33="X",3,G33="X",4),0)} -> 0
C34: MANTENIMIENTO CARTELERAS PDP | F34: X | H34: Se debe iniciar en Arbril 2026 con la implam¿ntación de la documentación del PDP-360° | I34: {=IFERROR(_xlfn.IFS(D34="X",1,E34="X",2,F34="X",3,G34="X",4),0)} -> 3 | K34: x | L34: x | M34: x | P34: 46113 | R34: los recursos ya fueron asignados con la contratacióndel PDP-360°

Sheet TÉCNICAS COMPET EET + PANSI
D2: EVALUACIÓN DEL ESTADO DE LA TECNICA ÁREA: TÉCNICAS - COMPETENCIAS REQUISITO LOPDP:2021, ARTÍCULO 10.j
D6: CAÓTICO | E6: PSEUDO - PROFESIONAL | G6: PROFESIONAL
D7: 1 | E7: MEDIO BAJO 2 | F7: MEDIO ALTO 3 | G7: 4 | H7: COMENTARIOS
D8: INEXISTENTE | E8: MODELO DE GESTIÓN EMPÍRICO | F8: ORG. IFORMAL PREVALECE | G8: MODELO DE GESTIÓN TÉCNICO
C9: TRIADA PDP | D9: X | I9: {=IFERROR(_xlfn.IFS(D9="X",1,E9="X",2,F9="X",3,G9="X",4),0)} -> 1
B10: VULNERABILIDADES TÉCNICAS - COMPETENCIAS | C10: SERIE ISO 27000 | D10: X | H10: EL AREA DE SEGURIDAD FISICA Y SEGURIDAD DE LA INFORMACION | I10: {=IFERROR(_xlfn.IFS(D10="X",1,E10="X",2,F10="X",3,G10="X",4),0)} -> 1
C11: NIS2, PLAN NACIONAL CIBERSEGURIDAD | E11: X | I11: {=IFERROR(_xlfn.IFS(D11="X",1,E11="X",2,F11="X",3,G11="X",4),0)} -> 2
C12: FUNDAMENTOS SISTEMAS DE GESTIÓN e ISO 19011 | D12: X | I12: {=IFERROR(_xlfn.IFS(D12="X",1,E12="X",2,F12="X",3,G12="X",4),0)} -> 1
C13: FUNDAMENTOS GESTIÓN DE PROYECTOS | E13: X | I13: {=IFERROR(_xlfn.IFS(D13="X",1,E13="X",2,F13="X",3,G13="X",4),0)} -> 2
C14: FUNDAMENTOS CONTROL ESTADÍSTICO DE PROCESOS | D14: X | I14: {=IFERROR(_xlfn.IFS(D14="X",1,E14="X",2,F14="X",3,G14="X",4),0)} -> 1
C15: FUNDAMENTOS ADMINISTRACIÓN EMPRESAS (ESTRATEGIA, GRC, OTROS) | D15: X | I15: {=IFERROR(_xlfn.IFS(D15="X",1,E15="X",2,F15="X",3,G15="X",4),0)} -> 1
C16: BUENAS PRÁCTICAS CIBERSEGURIDAD | D16: X | I16: {=IFERROR(_xlfn.IFS(D16="X",1,E16="X",2,F16="X",3,G16="X",4),0)} -> 1
I17: {=IFERROR(_xlfn.IFS(D17="X",1,E17="X",2,F17="X",3,G17="X",4),0)} -> 0
I18: {=IFERROR(_xlfn.IFS(D18="X",1,E18="X",2,F18="X",3,G18="X",4),0)} -> 0
H19: ESTADO DE LA TÉCNICA | I19: =AVERAGEIF(I9:I18,"<>0") -> 1.25
D21: ADECUACIÓN DEL NIVEL DE SEGURIDAD (PANSI) ÁREA: TÉCNICAS - COMPETENCIAS OBLIGACIÓN LOPDP:2021, ARTÍCULO 47.6 | I21: PANSI | K21: =AVERAGEIF(I28:I37,"<>0") -> 3
K24: REQUISITO ARTÍCULO 22.2 -RESOLUCIÓN 2025-0028-R (GARANTÍA DE INDEPENDENCIA PARA DPO) | U24: ESTATUS DEL COMPROMISO DE APLICABILIDAD
D25: CAÓTICO | E25: PSEUDO - PROFESIONAL | G25: PROFESIONAL
D26: 1 | E26: MEDIO BAJO 2 | F26: MEDIO ALTO 3 | G26: 4 | H26: ACCIONES MITIGADORAS | K26: RECURSOS NECESARIO | P26: COMPROMISOS DE APLICABILIDAD | U26: CUMPLIDO | V26: DEMORADO | W26: EN PROCESO
D27: INEXISTENTE | E27: MODELO DE GESTIÓN EMPÍRICO | F27: ORG. IFORMAL PREVALECE | G27: MODELO DE GESTIÓN TÉCNICO | H27: MEDIDAS, HERRAMIENTAS Y CONTROLES | K27: HUMANO | L27: TECNOLOGÍCO | M27: FINANCIERO | N27: INFRAESTRUCTURA | P27: FECHA PROBABLE | Q27: INVERSIÓN ESTIMADA | R27: COMENTARIOS
C28: TRIADA PDP | F28: X | H28: se inscribirá al lider del royecto en un diplomado para que tenga la certificación | I28: {=IFERROR(_xlfn.IFS(D28="X",1,E28="X",2,F28="X",3,G28="X",4),0)} -> 3 | K28: x | M28: x
B29: VULNERABILIDADES TÉCNICAS - COMPETENCIAS | C29: SERIE ISO 27000 | F29: X | I29: {=IFERROR(_xlfn.IFS(D29="X",1,E29="X",2,F29="X",3,G29="X",4),0)} -> 3
C30: NIS2, PLAN NACIONAL CIBERSEGURIDAD | F30: X | H30: se definirá un programa de autoformación . El SG-PDP contratado tiene sis sesiones de formación en estos temas. | I30: {=IFERROR(_xlfn.IFS(D30="X",1,E30="X",2,F30="X",3,G30="X",4),0)} -> 3 | K30: x | M30: x | P30: 46174
C31: FUNDAMENTOS SISTEMAS DE GESTIÓN e ISO 19011 | I31: {=IFERROR(_xlfn.IFS(D31="X",1,E31="X",2,F31="X",3,G31="X",4),0)} -> 0
C32: FUNDAMENTOS GESTIÓN DE PROYECTOS | F32: X | I32: {=IFERROR(_xlfn.IFS(D32="X",1,E32="X",2,F32="X",3,G32="X",4),0)} -> 3
C33: FUNDAMENTOS CONTROL ESTADÍSTICO DE PROCESOS | I33: {=IFERROR(_xlfn.IFS(D33="X",1,E33="X",2,F33="X",3,G33="X",4),0)} -> 0
C34: FUNDAMENTOS ADMINISTRACIÓN EMPRESAS (ESTRATEGIA, GRC, OTROS) | I34: {=IFERROR(_xlfn.IFS(D34="X",1,E34="X",2,F34="X",3,G34="X",4),0)} -> 0
C35: BUENAS PRÁCTICAS CIBERSEGURIDAD | I35: {=IFERROR(_xlfn.IFS(D35="X",1,E35="X",2,F35="X",3,G35="X",4),0)} -> 0
I36: {=IFERROR(_xlfn.IFS(D36="X",1,E36="X",2,F36="X",3,G36="X",4),0)} -> 0
I37: {=IFERROR(_xlfn.IFS(D37="X",1,E37="X",2,F37="X",3,G37="X",4),0)} -> 0

Sheet TÉCNICAS TECNOL EET + PANSI
D2: EVALUACIÓN DEL ESTADO DE LA TECNICA ÁREA: TÉCNICAS - TECNOLOGÍA REQUISITO LOPDP:2021, ARTÍCULO 10.j
D6: CAÓTICO | E6: PSEUDO - PROFESIONAL | G6: PROFESIONAL
D7: 1 | E7: MEDIO BAJO 2 | F7: MEDIO ALTO 3 | G7: 4 | H7: COMENTARIOS
D8: INEXISTENTE | E8: MODELO DE GESTIÓN EMPÍRICO | F8: ORG. IFORMAL PREVALECE | G8: MODELO DE GESTIÓN TÉCNICO
C9: INVENTARIO DE ACIVOS DE LOS DATOS E INFORMACIÓN | G9: X | H9: FALTA CATEGRIZAR LOS ACTIVOS | I9: {=IFERROR(_xlfn.IFS(D9="X",1,E9="X",2,F9="X",3,G9="X",4),0)} -> 4
B10: VULNERABILIDADES TÉCNICAS - TECNOLOGÍA | C10: GESTIÓN PLATAFORMAS DIGITALES | F10: X | I10: {=IFERROR(_xlfn.IFS(D10="X",1,E10="X",2,F10="X",3,G10="X",4),0)} -> 3
C11: GESTIÓN SERVICIOS NUBE | E11: X | H11: HAY QUE REVISARLO YA QUE ALGUNOS | I11: {=IFERROR(_xlfn.IFS(D11="X",1,E11="X",2,F11="X",3,G11="X",4),0)} -> 2
C12: GESTIÓN ACCESOS REMOTOS | G12: X | I12: {=IFERROR(_xlfn.IFS(D12="X",1,E12="X",2,F12="X",3,G12="X",4),0)} -> 4
C13: GESTIÓN DE CLAVES | F13: X | H13: NO HAY DOBLE FACTOR DE SEGURIDAD | I13: {=IFERROR(_xlfn.IFS(D13="X",1,E13="X",2,F13="X",3,G13="X",4),0)} -> 3
C14: GESTIÓN DE EQUIPOS CRÍTICOS | F14: X | I14: {=IFERROR(_xlfn.IFS(D14="X",1,E14="X",2,F14="X",3,G14="X",4),0)} -> 3
C15: GESTIÓN DE EQUIPOS PERSONALES (PATD) | G15: X | I15: {=IFERROR(_xlfn.IFS(D15="X",1,E15="X",2,F15="X",3,G15="X",4),0)} -> 4
C16: GESTIÓN DE PRIVILEGIOS (ZERO TRUST) | G16: X | I16: {=IFERROR(_xlfn.IFS(D16="X",1,E16="X",2,F16="X",3,G16="X",4),0)} -> 4
C17: GESTIÓN SIMULACROS Y CIBERSEGURIDAD | G17: X | I17: {=IFERROR(_xlfn.IFS(D17="X",1,E17="X",2,F17="X",3,G17="X",4),0)} -> 4
C18: ENCRIPTACIÓN Y SEUDONIMIZACIÓN | D18: X | I18: {=IFERROR(_xlfn.IFS(D18="X",1,E18="X",2,F18="X",3,G18="X",4),0)} -> 1
H19: ESTADO DE LA TÉCNICA | I19: =AVERAGEIF(I9:I18,"<>0") -> 3.2
D21: ADECUACIÓN DEL NIVEL DE SEGURIDAD (PANSI) ÁREA: TÉCNICAS - TECNOLOGÍA OBLIGACIÓN LOPDP:2021, ARTÍCULO 47.6 | I21: PANSI | K21: =AVERAGEIF(I28:I37,"<>0") -> 3.7142857
K24: REQUISITO ARTÍCULO 22.2 -RESOLUCIÓN 2025-0028-R (GARANTÍA DE INDEPENDENCIA PARA DPO) | U24: ESTATUS DEL COMPROMISO DE APLICABILIDAD
D25: CAÓTICO | E25: PSEUDO - PROFESIONAL | G25: PROFESIONAL
D26: 1 | E26: MEDIO BAJO 2 | F26: MEDIO ALTO 3 | G26: 4 | H26: ACCIONES MITIGADORAS | K26: RECURSOS NECESARIO | P26: COMPROMISOS DE APLICABILIDAD | U26: CUMPLIDO | V26: DEMORADO | W26: EN PROCESO
D27: INEXISTENTE | E27: MODELO DE GESTIÓN EMPÍRICO | F27: ORG. IFORMAL PREVALECE | G27: MODELO DE GESTIÓN TÉCNICO | H27: MEDIDAS, HERRAMIENTAS Y CONTROLES | K27: HUMANO | L27: TECNOLOGÍCO | M27: FINANCIERO | N27: INFRAESTRUCTURA | P27: FECHA PROBABLE | Q27: INVERSIÓN ESTIMADA | R27: COMENTARIOS
C28: INVENTARIO DE ACIVOS DE LOS DATOS E INFORMACIÓN | G28: X | I28: {=IFERROR(_xlfn.IFS(D28="X",1,E28="X",2,F28="X",3,G28="X",4),0)} -> 4
B29: VULNERABILIDADES TÉCNICAS - TECNOLOGÍA | C29: GESTIÓN PLATAFORMAS DIGITALES | I29: {=IFERROR(_xlfn.IFS(D29="X",1,E29="X",2,F29="X",3,G29="X",4),0)} -> 0
C30: GESTIÓN SERVICIOS NUBE | F30: X | H30: cloud estudio debe ser contactado para evluar sus SG-PDP este oara core faciero. Tambien con puntonet que administra respaldos y segura contnuidad de operaciones | I30: {=IFERROR(_xlfn.IFS(D30="X",1,E30="X",2,F30="X",3,G30="X",4),0)} -> 3 | K30: x
C31: GESTIÓN ACCESOS REMOTOS | G31: X | I31: {=IFERROR(_xlfn.IFS(D31="X",1,E31="X",2,F31="X",3,G31="X",4),0)} -> 4
C32: GESTIÓN DE CLAVES | I32: {=IFERROR(_xlfn.IFS(D32="X",1,E32="X",2,F32="X",3,G32="X",4),0)} -> 0
C33: GESTIÓN DE EQUIPOS CRÍTICOS | I33: {=IFERROR(_xlfn.IFS(D33="X",1,E33="X",2,F33="X",3,G33="X",4),0)} -> 0
C34: GESTIÓN DE EQUIPOS PERSONALES (PATD) | G34: X | I34: {=IFERROR(_xlfn.IFS(D34="X",1,E34="X",2,F34="X",3,G34="X",4),0)} -> 4
C35: GESTIÓN DE PRIVILEGIOS (ZERO TRUST) | G35: X | I35: {=IFERROR(_xlfn.IFS(D35="X",1,E35="X",2,F35="X",3,G35="X",4),0)} -> 4
C36: GESTIÓN SIMULACROS Y CIBERSEGURIDAD | G36: X | I36: {=IFERROR(_xlfn.IFS(D36="X",1,E36="X",2,F36="X",3,G36="X",4),0)} -> 4
C37: ENCRIPTACIÓN Y SEUDONIMIZACIÓN | F37: X | H37: realizar analisis de proyecto para cotizar, contratar , implantar | I37: {=IFERROR(_xlfn.IFS(D37="X",1,E37="X",2,F37="X",3,G37="X",4),0)} -> 3 | K37: x | L37: x | M37: x | N37: x | P37: 46266 | Q37: Por definir | R37: se debe incluir resolucion de la seps para canales seguros.

Sheet DASHBOARD EET - PANSI
D5: ESTADO DE LA TÉCNICA POR AREAS 2025 | Q5: ESTADO DE LA TÉCNICA POR AREAS PROYECTADO 2026

Sheet NIVEL DE SEGURIDAD
D3: CALIFICACIÓN DEL NIVEL DE SEGURIDAD SOBRE CUATRO RASGOS ORGANIZACIONALES
L5: REQUISITO ARTÍCULO 22.2 -RESOLUCIÓN 2025-0028-R (GARANTÍA DE INDEPENDENCIA PARA DPO)
D7: CAÓTICO | E7: PSEUDO - PROFESIONAL | G7: PROFESIONAL | L7: RECURSOS NECESARIO | Q7: COMPROMISOS DE APLICABILIDAD
C8: RASGOS ORGANIZACONALES | D8: 1 | E8: MEDIO BAJO 2 | F8: MEDIO ALTO 3 | G8: 4 | H8: COMENTARIOS - AMENAZAS - ALERTAS | I8: NIVEL INICIAL | J8: NIVEL ESPERADO | L8: HUMANO | M8: TECNOLOGÍCO | N8: FINANCIERO | O8: INFRAESTRUCTURA | Q8: FECHA PROBABLE | R8: INVERSIÓN ESTIMADA | S8: COMENTARIOS
C9: ESTADO DE LA TÉCNICA | E9: =+'Análisis NSI'!AC10 -> 2.0797817 | H9: COMENTARIO: LA PLANIFICACIÓN DE ADECUACIÓN DEL NIVEL DE SEGURIDAD INICIAL DESCRITAS EN CADA UNA DE LAS 5 ÁREAS DEL ESTADO DE LA TÉCNICA PERMITIRÁ ELEVAR LA CALIFICACIÓN DENTRO DEL PRIMER TRIMESTRE 2026 | I9: =+E9 -> 2.0797817 | J9: META >3 | L9: X | M9: X | N9: X | O9: X | Q9: 46082 | S9: 1.- Los compromisos del primer trimestre deben ser cubiertos en su totalidad ya que son la base sobre la que se construirá el esquema sistémico para la protección de datos personales. 2.- La mayor inversión ya está realizada con la compra del esquema sistémico predocumentado para protección de datos personales Skillman-PDP. Otras inversiones como señalética para avisos en puntos de interacció Titular-Responsable o programa de carteleras informativas PDP serán inculidos una vez se aprueben las cotizaciones presentadas y el presupuesto para cubrir estos rubros
C10: SISTEMA DE GESTIÓN PARA EL GRC | D10: INEXISTENTE | E10: NO VALIDADO | F10: VALIDADO Y POCO MANTENIDO, NO MEJORA NI RESILIENTE | G10: VALIDADO, ANTENIDO, MEJORADO Y RESILIENTE | H10: COMENTARIO: INICIO UN PROYECTO PARA VALIDAR UN SG-PDP. CONTRATO UN DPD QUE SERÁ EL SUPERVISOR DEL PANSI QUE INCLUYE EL PROYECTO SG-PDP | I10: 2 | J10: META >3 | L10: X | N10: X | O10: X | Q10: 46266 | S10: 1.- Se inicia con la implantación de la documentación del esquema sistémico predocumentado Skillman-PDP. 2.- La personalización de la docuemntación de Skillman-PDP puede extenderse hasta abril 2026 ya que es probable que demoren las entregas de EIPD de algunos proveedores de plataformas digitales. 3.- Las méticas e indicadores de desempeño iniciales se alimentarán iniciando Abril 2026. El SG-PDP iniciaría con los indicadores Nivel de seguridad (47.6 LOPDP:2021) y Evaluación del DPO (22.2 de R-028-2025). 4.- PAra los meses de septiembre u octubre se estaría realizando la auditoría interna para validar el SG-PDP
C11: MODELO PARA TOMA DE DECISIONES | D11: INEXISTENTE | E11: POR JERARQUIAS | F11: COMBINA INDICADORES Y PREVALECE JERARQUIAS | G11: INDICADORES | I11: 2 | J11: META >3 | L11: X | O11: X | Q11: 46174 | S11: 1.- Los compromisos del primer trimestre deben ser cubiertos en su totalidad ya que el fortalecimiento del estado de la técnica, impacta de manera directa y positiva sobre el rasgo organizacional Toma de Desiciones Informadas. El programa de profesionalización debe incluir la gestión de métricas e indicdores dentro del 1T26 2.- Las méticas e indicadores de desempeño iniciales se alimentarán iniciando Abril 2026. El SG-PDP iniciaría con los indicadores Nivel de seguridad (47.6 LOPDP:2021) y Evaluación del DPO (22.2 de R-028-2025). 3.- El inicio de la toma de decisiones informadas depende de las capacitaciones del programa de profesionalización y cosncienciación. Para junio o julio 2026 se podrán observar las tendencias iniciales de los indicadores Nivel de Seguridad y Evaluación del DPO además, del nivel de Seguridad de 3ras Partes. 4.- LA garantía de que el nivel de madurez organizacional se mantenga y continue fortaleciendose dependerá de la continuidad que se le de a los programas de competencias técnicas y conscienciación derivado de los simulacros y las lecciones tomadas luego de su realización.
C12: GESTIÓN DE RESULTADOS | D12: INEXISTENTE | E12: REACTIVO POR ATENCIÓN DE EMERGENCIAS | F12: COMBINADO Y PREVALECE LO REACTIVO | G12: RIESGOS Y CONTINUIDAD DEL NEGOCIO | I12: 2 | J12: META >3 | L12: X | O12: X | Q12: 46174 | S12: 1.- Los compromisos del primer trimestre deben ser cubiertos en su totalidad ya que el fortalecimiento del estado de la técnica, impacta de manera directa y positiva sobre el rasgo organizacional Toma de Desiciones Informadas. El programa de profesionalización debe incluir la gestión de métricas e indicdores dentro del 1T26 2.- Con el fortalecimiento del estado de la técnica y el inicio del seguimiento a la tendencia de métricas e indicadores para su ajuste o reforzamiento, el rasgo organizacional Gestión de Resultados será fortalecido.
